try: #只要try內部發生錯誤 會來到except
  10/0
  #print(a)
except:  
  print("錯誤發生") 

